Workbook
Name UPDATE: 'Tata-input'!$E$1

Sheet Tata Comm
A1: (₹ Crores/10 Millions) | D1: =+'Tata-input'!B1 -> TATA COMMUNICATIONS LTD | L1: =+'Tata-input'!K41 -> 45657 | M1: << Latest available quarterly results
A2: Narration | B2: =+'Tata-input'!B16 -> 42094 | C2: =+'Tata-input'!C16 -> 42460 | D2: =+'Tata-input'!D16 -> 42825 | E2: =+'Tata-input'!E16 -> 43190 | F2: =+'Tata-input'!F16 -> 43555 | G2: =+'Tata-input'!G16 -> 43921 | H2: =+'Tata-input'!H16 -> 44286 | I2: =+'Tata-input'!I16 -> 44651 | ... K2: =+'Tata-input'!K16 -> 45382 | L2: Last 4 Quarters | M2: Total 10 Yrs | N2: TRENDS: | O2: 10Yr | P2: 7Yr | Q2: 5Yr | R2: 3Yr | S2: TTM
A3: Sales | B3: =+'Tata-input'!B17 -> 19913.34 | C3: =+'Tata-input'!C17 -> 18148.58 | D3: =+'Tata-input'!D17 -> 17619.73 | E3: =+'Tata-input'!E17 -> 16771.69 | F3: =+'Tata-input'!F17 -> 16524.95 | G3: =+'Tata-input'!G17 -> 17067.99 | H3: =+'Tata-input'!H17 -> 17100.1 | I3: =+'Tata-input'!I17 -> 16724.73 | ... K3: =+'Tata-input'!K17 -> 20968.82 | L3: =IF(N66=TRUE,"",SUM('Tata-input'!H42:K42)) -> 22850.99 | N3: Sales Growth | O3: =IF(B3=0,"",POWER($K3/B3,1/9)-1) -> 0.0057550206 | P3: =IF(D3=0,"",POWER($K3/D3,1/7)-1) -> 0.025171187 | Q3: =IF(F3=0,"",POWER($K3/F3,1/5)-1) -> 0.048785725 | R3: =IF(H3=0,"",POWER($K3/H3, 1/3)-1) -> 0.070348276 | S3: =IF(N66=TRUE,"",L3/K3-1) -> 0.089760416
A4: Operating Profit | B4: =+'Tata-input'!B17-'Tata-input'!B18+'Tata-input'!B19-SUM('Tata-input'!B20:B24) -> 2994.05 | C4: =+'Tata-input'!C17-'Tata-input'!C18+'Tata-input'!C19-SUM('Tata-input'!C20:C24) -> 2434.24 | D4: =+'Tata-input'!D17-'Tata-input'!D18+'Tata-input'!D19-SUM('Tata-input'!D20:D24) -> 2405.9 | E4: =+'Tata-input'!E17-'Tata-input'!E18+'Tata-input'!E19-SUM('Tata-input'!E20:E24) -> 2412.22 | F4: =+'Tata-input'!F17-'Tata-input'!F18+'Tata-input'!F19-SUM('Tata-input'!F20:F24) -> 2744.85 | G4: =+'Tata-input'!G17-'Tata-input'!G18+'Tata-input'!G19-SUM('Tata-input'!G20:G24) -> 3288.95 | H4: =+'Tata-input'!H17-'Tata-input'!H18+'Tata-input'!H19-SUM('Tata-input'!H20:H24) -> 4260.58 | I4: =+'Tata-input'!I17-'Tata-input'!I18+'Tata-input'!I19-SUM('Tata-input'!I20:I24) -> 4226.72 | ... K4: =+'Tata-input'!K17-'Tata-input'!K18+'Tata-input'!K19-SUM('Tata-input'!K20:K24) -> 4230.1 | L4: =+IF(N66=TRUE,"",SUM('Tata-input'!H50:K50)) -> 4490.84 | N4: OPM | O4: =IF(SUM(B3:$K$3)=0,"",SUMPRODUCT(B5:$K$5,B3:$K$3)/SUM(B3:$K$3)) -> 0.18645723 | P4: =IF(SUM(E3:$K$3)=0,"",SUMPRODUCT(E5:$K$5,E3:$K$3)/SUM(E3:$K$3)) -> 0.20717371 | Q4: =IF(SUM(G3:$K$3)=0,"",SUMPRODUCT(G5:$K$5,G3:$K$3)/SUM(G3:$K$3)) -> 0.2265842 | R4: =IF(SUM(I3:$K$3)=0, "", SUMPRODUCT(I5:$K$5,I3:$K$3)/SUM(I3:$K$3)) -> 0.23004923 | S4: =IF(N66=TRUE,"",L5) -> 0.19652715
A5: Operating Profit Margin (OPM%) | B5: =IF(B4>0,B4/B3,0) -> 0.15035398 | C5: =IF(C4>0,C4/C3,0) -> 0.1341284 | D5: =IF(D4>0,D4/D3,0) -> 0.13654579 | E5: =IF(E4>0,E4/E3,0) -> 0.14382689 | F5: =IF(F4>0,F4/F3,0) -> 0.16610338 | G5: =IF(G4>0,G4/G3,0) -> 0.19269697 | H5: =IF(H4>0,H4/H3,0) -> 0.24915527 | I5: =IF(I4>0,I4/I3,0) -> 0.25272276 | ... K5: =IF(K4>0,K4/K3,0) -> 0.20173286 | L5: =+IF(N66=TRUE,"",IF(L4>0,L4/L3,0)) -> 0.19652715 | N5: PAT Growth | O5: =IF(B13=0,"",POWER($K13/B13,1/9)-1) -> 1.0868591 | P5: =IF(D13=0,"",POWER($K13/D13,1/7)-1) -> -0.033913979 | Q5: =IF(F13=0,"",POWER($K13/F13,1/5)-1) -> -2.6370116 | R5: =IF(H13=0,"",POWER($K13/H13, 1/3)-1) -> -0.081738569 | S5: =+IF(N66=TRUE,"",L13/K13-1) -> 0.15373732
A6: Other Income | B6: =+'Tata-input'!B25 -> 291.24 | C6: =+'Tata-input'!C25 -> 82.42 | D6: =+'Tata-input'!D25 -> 1293.82 | E6: =+'Tata-input'!E25 -> -115.86 | F6: =+'Tata-input'!F25 -> 62.5 | G6: =+'Tata-input'!G25 -> -320.83 | H6: =+'Tata-input'!H25 -> 82.04 | I6: =+'Tata-input'!I25 -> 338.05 | ... K6: =+'Tata-input'!K25 -> 46.81 | L6: =IF(N66=TRUE,"",+SUM('Tata-input'!H44:K44)) -> 139.2 | M6: =SUM(G6:K6) -> 585.57 | N6: Avg. PE | O6: =IF(ISERROR(AVERAGEIF(B44:$L44,">0")),"",AVERAGEIF(B44:$L44,">0")) -> 961.8402 | P6: =IF(ISERROR(AVERAGEIF(E44:$L44,">0")),"",AVERAGEIF(E44:$L44,">0")) -> 31.696218 | Q6: =IF(ISERROR(AVERAGEIF(G44:$L44,">0")),"",AVERAGEIF(G44:$L44,">0")) -> 31.696218 | R6: =IF(ISERROR(AVERAGEIF(I44:$L44,">0")),"",AVERAGEIF(I44:$L44,">0")) -> 34.188414 | S6: =IF(N66=TRUE,"",O10) -> 34.502242
A7: EBITDA | B7: =+SUM(B4+B6) -> 3285.29 | C7: =+SUM(C4+C6) -> 2516.66 | D7: =+SUM(D4+D6) -> 3699.72 | E7: =+SUM(E4+E6) -> 2296.36 | F7: =+SUM(F4+F6) -> 2807.35 | G7: =+SUM(G4+G6) -> 2968.12 | H7: =+SUM(H4+H6) -> 4342.62 | I7: =+SUM(I4+I6) -> 4564.77 | ... K7: =+SUM(K4+K6) -> 4276.91 | L7: =++IF(N66=TRUE,"",SUM(L4+L6)) -> 4630.04 | M7: =SUM(G7:K7) -> 20910.15
A8: Interest | B8: =+'Tata-input'!B27 -> 750.79 | C8: =+'Tata-input'!C27 -> 409.06 | D8: =+'Tata-input'!D27 -> 367.19 | E8: =+'Tata-input'!E27 -> 344.45 | F8: =+'Tata-input'!F27 -> 396.55 | G8: =+'Tata-input'!G27 -> 470.74 | H8: =+'Tata-input'!H27 -> 420.2 | I8: =+'Tata-input'!I27 -> 360.25 | ... K8: =+'Tata-input'!K27 -> 644.15 | L8: =+IF(N66=TRUE,"",SUM('Tata-input'!H46:K46)) -> 736.67 | M8: =SUM(G8:K8) -> 2327.8
A9: Depreciation | B9: =+'Tata-input'!B26 -> 2161.09 | C9: =+'Tata-input'!C26 -> 1864.29 | D9: =+'Tata-input'!D26 -> 1865.77 | E9: =+'Tata-input'!E26 -> 1906.3 | F9: =+'Tata-input'!F26 -> 2067.6 | G9: =+'Tata-input'!G26 -> 2357.72 | H9: =+'Tata-input'!H26 -> 2313.87 | I9: =+'Tata-input'!I26 -> 2204.54 | ... K9: =+'Tata-input'!K26 -> 2469.67 | L9: =IF(N66=TRUE,"",+SUM('Tata-input'!H45:K45)) -> 2598.51 | M9: =SUM(G9:K9) -> 11607.61 | N9: CMP | O9: =+'Tata-input'!B8 -> 1352.5
A10: Profit before tax (PBT) | B10: =+'Tata-input'!B28 -> 373.41 | C10: =+'Tata-input'!C28 -> 243.31 | D10: =+'Tata-input'!D28 -> 1466.76 | E10: =+'Tata-input'!E28 -> 45.61 | F10: =+'Tata-input'!F28 -> 343.2 | G10: =+'Tata-input'!G28 -> 139.66 | H10: =+'Tata-input'!H28 -> 1608.55 | I10: =+'Tata-input'!I28 -> 1999.98 | ... K10: =+'Tata-input'!K28 -> 1163.09 | L10: =IF(N66=TRUE,"",+SUM('Tata-input'!H47:K47)) -> 1294.86 | N10: P/E | O10: =IF(N66=TRUE,O15/K13,O15/L13) -> 34.502242
A11: Tax | B11: =+'Tata-input'!B29 -> 370.46 | C11: =+'Tata-input'!C29 -> 232.85 | D11: =+'Tata-input'!D29 -> 236.38 | E11: =+'Tata-input'!E29 -> 354.92 | F11: =+'Tata-input'!F29 -> 273.32 | G11: =+'Tata-input'!G29 -> 226.67 | H11: =+'Tata-input'!H29 -> 354.89 | I11: =+'Tata-input'!I29 -> 522.13 | ... K11: =+'Tata-input'!K29 -> 213.5 | L11: =IF(N66=TRUE,"",+SUM('Tata-input'!H48:K48)) -> 202.12
A12: Tax% | B12: =B11/B10 -> 0.99209984 | C12: =C11/C10 -> 0.95700958 | D12: =D11/D10 -> 0.16115793 | E12: =E11/E10 -> 7.7816268 | F12: =F11/F10 -> 0.79638695 | G12: =G11/G10 -> 1.623013 | H12: =H11/H10 -> 0.22062727 | I12: =I11/I10 -> 0.26106761 | ... K12: =K11/K10 -> 0.18356275 | L12: =+IF(N66=TRUE,"",L11/L10) -> 0.1560941 | N12: P/B | O12: =+'Tata-input'!B9/SUM('Tata-input'!K57:K58) -> 21.577373
A13: Net profit after tax (PAT) | B13: =+'Tata-input'!B30 -> 1.29 | C13: =+'Tata-input'!C30 -> 8.68 | D13: =+'Tata-input'!D30 -> 1232.87 | E13: =+'Tata-input'!E30 -> -328.6 | F13: =+'Tata-input'!F30 -> -82.37 | G13: =+'Tata-input'!G30 -> -85.96 | H13: =+'Tata-input'!H30 -> 1250.63 | I13: =+'Tata-input'!I30 -> 1481.76 | ... K13: =+'Tata-input'!K30 -> 968.34 | L13: =IF(N66=TRUE,"",+SUM('Tata-input'!H49:K49)) -> 1117.21 | M13: =SUM(G13:K13) -> 5410.73 | N13: P/E*P/B | O13: =O10*O12 -> 744.46774
A14: Net Profit Margin (NPM%) | B14: =B13/B3 -> 6.4780695e-05 | C14: =C13/C3 -> 0.00047827433 | D14: =D13/D3 -> 0.069970993 | E14: =E13/E3 -> -0.01959254 | F14: =F13/F3 -> -0.0049845839 | G14: =G13/G3 -> -0.0050363282 | H14: =H13/H3 -> 0.07313583 | I14: =I13/I3 -> 0.088596946 | ... K14: =K13/K3 -> 0.046179995 | L14: =+IF(N66=TRUE,"",L13/L3) -> 0.048891098 | N14: Div Yield | O14: ='Tata-input'!K31/'Tata-input'!B9 -> 0.012347505
A15: Cash from Operating Activity (CFO) | B15: =+'Tata-input'!B82 -> 3028.34 | C15: =+'Tata-input'!C82 -> 2362.69 | D15: =+'Tata-input'!D82 -> 2393.5 | E15: =+'Tata-input'!E82 -> 1712.81 | F15: =+'Tata-input'!F82 -> 1844.33 | G15: =+'Tata-input'!G82 -> 2524.76 | H15: =+'Tata-input'!H82 -> 3179.83 | I15: =+'Tata-input'!I82 -> 4203.82 | ... K15: =+'Tata-input'!K82 -> 3182 | L15: CFO | M15: =SUM(G15:K15) -> 17474.76 | N15: Market Cap | O15: =+'Tata-input'!B9 -> 38546.25
A16: Capex {(NFA+WIP) change+Dep} | C16: =+'Tata-input'!C62+'Tata-input'!C63-'Tata-input'!B62-'Tata-input'!B63+'Tata-input'!C26 -> 1765.76 | D16: =+'Tata-input'!D62+'Tata-input'!D63-'Tata-input'!C62-'Tata-input'!C63+'Tata-input'!D26 -> -1698.43 | E16: =+'Tata-input'!E62+'Tata-input'!E63-'Tata-input'!D62-'Tata-input'!D63+'Tata-input'!E26 -> 1543.72 | F16: =+'Tata-input'!F62+'Tata-input'!F63-'Tata-input'!E62-'Tata-input'!E63+'Tata-input'!F26 -> 2401.48 | G16: =+'Tata-input'!G62+'Tata-input'!G63-'Tata-input'!F62-'Tata-input'!F63+'Tata-input'!G26 -> 3824.03 | H16: =+'Tata-input'!H62+'Tata-input'!H63-'Tata-input'!G62-'Tata-input'!G63+'Tata-input'!H26 -> 1209.36 | I16: =+'Tata-input'!I62+'Tata-input'!I63-'Tata-input'!H62-'Tata-input'!H63+'Tata-input'!I26 -> 1980.67 | J16: =+'Tata-input'!J62+'Tata-input'!J63-'Tata-input'!I62-'Tata-input'!I63+'Tata-input'!J26 -> 2120.79 | K16: =+'Tata-input'!K62+'Tata-input'!K63-'Tata-input'!J62-'Tata-input'!J63+'Tata-input'!K26 -> 5616.47 | L16: ='Tata-input'!B68 -> 26.4 | M16: =SUM(G16:K16) -> 14751.32
A17: FCF | C17: =+C15-C16 -> 596.93 | D17: =+D15-D16 -> 4091.93 | E17: =+E15-E16 -> 169.09 | F17: =+F15-F16 -> -557.15 | G17: =+G15-G16 -> -1299.27 | H17: =+H15-H16 -> 1970.47 | I17: =+I15-I16 -> 2223.15 | J17: =+J15-J16 -> 2263.56 | K17: =+K15-K16 -> -2434.47 | L17: FCF | M17: =+M15-M16 -> 2723.44 | N17: =SUM(B43:K43) -> 3358.4 | O17: Total Retained Earnings (RE) in 10 Yrs (A)
A18: Total Debt (D) | B18: =+'Tata-input'!B59 -> 13075.72 | C18: =+'Tata-input'!C59 -> 14230.86 | D18: =+'Tata-input'!D59 -> 9213.6 | E18: =+'Tata-input'!E59 -> 8926.97 | F18: =+'Tata-input'!F59 -> 9934.94 | G18: =+'Tata-input'!G59 -> 12413.49 | H18: =+'Tata-input'!H59 -> 11393.6 | I18: =+'Tata-input'!I59 -> 9121.54 | ... K18: =+'Tata-input'!K59 -> 11263.17 | L18: FCFE (Post Int. exp.) | M18: =+M17-M8 -> 395.64 | N18: =L45-IF(N21>0,N21*'Tata-input'!B6,B45) -> 31036.5 | O18: Total increase in Mcap in 10 yrs (B)
A19: Share Capital | B19: =+'Tata-input'!B57 -> 285 | C19: =+'Tata-input'!C57 -> 285 | D19: =+'Tata-input'!D57 -> 285 | E19: =+'Tata-input'!E57 -> 285 | F19: =+'Tata-input'!F57 -> 285 | G19: =+'Tata-input'!G57 -> 285 | H19: =+'Tata-input'!H57 -> 285 | I19: =+'Tata-input'!I57 -> 285 | ... K19: =+'Tata-input'!K57 -> 285 | L19: Total Div 10 Yrs | M19: =+SUM(B41:K41) -> 2884.2 | N19: =N18/N17 -> 9.2414543 | O19: Value created per INR of RE (B/A)
A20: Dividend Paid (Div) Without DDT | B20: =+'Tata-input'!B31 -> 156.75 | C20: =+'Tata-input'!C31 -> 122.55 | D20: =+'Tata-input'!D31 -> 171 | E20: =+'Tata-input'!E31 -> 128.25 | F20: =+'Tata-input'!F31 -> 128.25 | G20: =+'Tata-input'!G31 -> 114 | H20: =+'Tata-input'!H31 -> 399 | I20: =+'Tata-input'!I31 -> 589.95 | ... K20: =+'Tata-input'!K31 -> 475.95 | L20: Inc. in Debt in 10Yrs | M20: =+K18-G18 -> -1150.32
A21: Cash + Investments (CI +NCI) | B21: =+'Tata-input'!B64+'Tata-input'!B69 -> 3388.65 | C21: =+'Tata-input'!C64+'Tata-input'!C69 -> 3813.49 | D21: =+'Tata-input'!D64+'Tata-input'!D69 -> 3513.25 | E21: =+'Tata-input'!E64+'Tata-input'!E69 -> 2545.77 | F21: =+'Tata-input'!F64+'Tata-input'!F69 -> 2343.35 | G21: =+'Tata-input'!G64+'Tata-input'!G69 -> 2472.23 | H21: =+'Tata-input'!H64+'Tata-input'!H69 -> 3160.46 | I21: =+'Tata-input'!I64+'Tata-input'!I69 -> 2308.62 | ... K21: =+'Tata-input'!K64+'Tata-input'!K69 -> 2450.67 | L21: Cash+Investments | M21: =+K21 -> 2450.67 | N21: 0 | O21: Closing share price on March 31, 10 years back
A22: Net Debt | B22: =B18-B60 -> 11454.57 | C22: =C18-C60 -> 12254.59 | D22: =D18-D60 -> 8134.31 | E22: =E18-E60 -> 7631.39 | F22: =F18-F60 -> 9082.86 | G22: =G18-G60 -> 11504.36 | H22: =H18-H60 -> 10466.5 | I22: =I18-I60 -> 8378.15 | ... K22: =K18-K60 -> 10420.72 | L22: FCF/CFO | M22: =+M17/M15 -> 0.15584992
A23: Self-Sustainable Growth Rate (SSGR) | E23: =AVERAGE(C33:E33)*AVERAGE(C14:E14)*(1-AVERAGE(C42:E42))-AVERAGE(C66:E66) -> -0.24431078 | F23: =AVERAGE(D33:F33)*AVERAGE(D14:F14)*(1-AVERAGE(D42:F42))-AVERAGE(D66:F66) -> -0.14100347 | G23: =AVERAGE(E33:G33)*AVERAGE(E14:G14)*(1-AVERAGE(E42:G42))-AVERAGE(E66:G66) -> -0.21213928 | H23: =AVERAGE(F33:H33)*AVERAGE(F14:H14)*(1-AVERAGE(F42:H42))-AVERAGE(F66:H66) -> -0.13332075 | I23: =AVERAGE(G33:I33)*AVERAGE(G14:I14)*(1-AVERAGE(G42:I42))-AVERAGE(G66:I66) -> -0.10528802 | J23: =AVERAGE(H33:J33)*AVERAGE(H14:J14)*(1-AVERAGE(H42:J42))-AVERAGE(H66:J66) -> -0.11951393 | K23: =AVERAGE(I33:K33)*AVERAGE(I14:K14)*(1-AVERAGE(I42:K42))-AVERAGE(I66:K66) -> -0.1241323 | L23: Interest Outgo | M23: =+M52 -> 11517.73
L24: Change in 10 Yrs
A25: Trade Receivables | B25: =+'Tata-input'!B67 -> 2487 | C25: =+'Tata-input'!C67 -> 3018.86 | D25: =+'Tata-input'!D67 -> 2590.04 | E25: =+'Tata-input'!E67 -> 2953.47 | F25: =+'Tata-input'!F67 -> 2968.45 | G25: =+'Tata-input'!G67 -> 3228.87 | H25: =+'Tata-input'!H67 -> 2607.68 | I25: =+'Tata-input'!I67 -> 2582.13 | ... K25: =+'Tata-input'!K67 -> 3758.36 | L25: =+B25-K25 -> -1271.36
A26: Inventory | B26: =+'Tata-input'!B68 -> 26.4 | C26: =+'Tata-input'!C68 -> 25.42 | D26: =+'Tata-input'!D68 -> 19.2 | E26: =+'Tata-input'!E68 -> 26.99 | F26: =+'Tata-input'!F68 -> 76.58 | G26: =+'Tata-input'!G68 -> 72.97 | H26: =+'Tata-input'!H68 -> 34.44 | I26: =+'Tata-input'!I68 -> 37.88 | ... K26: =+'Tata-input'!K68 -> 83.54 | L26: =+B26-K26 -> -57.14
A28: PBT/Avg. NFA (<10%,>25%) | C28: =C10/(AVERAGE(B38:C38)) -> 0.016695011 | D28: =D10/(AVERAGE(C38:D38)) -> 0.11561891 | E28: =E10/(AVERAGE(D38:E38)) -> 0.0041988396 | F28: =F10/(AVERAGE(E38:F38)) -> 0.03107861 | G28: =G10/(AVERAGE(F38:G38)) -> 0.011610483 | H28: =H10/(AVERAGE(G38:H38)) -> 0.1324575 | I28: =I10/(AVERAGE(H38:I38)) -> 0.17812584 | J28: =J10/(AVERAGE(I38:J38)) -> 0.19252483 | K28: =K10/(AVERAGE(J38:K38)) -> 0.097057661
A29: ROE on Avg Equity (<7%,>25%) | C29: =C13/AVERAGE(B49:C49) -> -0.41441872 | D29: =D13/AVERAGE(C49:D49) -> 2.007049 | E29: =E13/AVERAGE(D49:E49) -> -0.31426631 | F29: =F13/AVERAGE(E49:F49) -> -0.5188498 | G29: =G13/AVERAGE(F49:G49) -> 0.11773972 | H29: =H13/AVERAGE(G49:H49) -> -2.1508814 | I29: =I13/AVERAGE(H49:I49) -> 2.8412061 | J29: =J13/AVERAGE(I49:J49) -> 1.4685774 | K29: =K13/AVERAGE(J49:K49) -> 0.58604161
A30: ROCE (EBIT on Avg CE/TA) (<10%,>35%) | C30: =(C10+C8)/AVERAGE('Tata-input'!B61:C61) -> 0.026469191 | D30: =(D10+D8)/AVERAGE('Tata-input'!C61:D61) -> 0.079510904 | E30: =(E10+E8)/AVERAGE('Tata-input'!D61:E61) -> 0.01921929 | F30: =(F10+F8)/AVERAGE('Tata-input'!E61:F61) -> 0.037447761 | G30: =(G10+G8)/AVERAGE('Tata-input'!F61:G61) -> 0.029009856 | H30: =(H10+H8)/AVERAGE('Tata-input'!G61:H61) -> 0.093411857 | I30: =(I10+I8)/AVERAGE('Tata-input'!H61:I61) -> 0.11529323 | J30: =(J10+J8)/AVERAGE('Tata-input'!I61:J61) -> 0.12430865 | K30: =(K10+K8)/AVERAGE('Tata-input'!J61:K61) -> 0.080528019
A31: Incremental ROE 3Yr Rolling | E31: =+(E13-B13)/SUM(B43:D43) -> -0.41624398 | F31: =+(F13-C13)/SUM(C43:E43) -> -0.18538125 | G31: =+(G13-D13)/SUM(D43:F43) -> -3.3438895 | H31: =+(H13-E13)/SUM(E43:G43) -> -1.8205849 | I31: =+(I13-F13)/SUM(F43:H43) -> 3.546378 | J31: =+(J13-G13)/SUM(G43:I43) -> 1.2192707 | K31: =+(K13-H13)/SUM(H43:J43) -> -0.095987623
A33: Net Fixed Asset Turnover (High is better) | C33: =+'Tata-input'!C17/(('Tata-input'!B62+'Tata-input'!C62)/2) -> 1.2452868 | D33: =+'Tata-input'!D17/(('Tata-input'!C62+'Tata-input'!D62)/2) -> 1.3888939 | E33: =+'Tata-input'!E17/(('Tata-input'!D62+'Tata-input'!E62)/2) -> 1.5439955 | F33: =+'Tata-input'!F17/(('Tata-input'!E62+'Tata-input'!F62)/2) -> 1.4964233 | G33: =+'Tata-input'!G17/(('Tata-input'!F62+'Tata-input'!G62)/2) -> 1.4189288 | H33: =+'Tata-input'!H17/(('Tata-input'!G62+'Tata-input'!H62)/2) -> 1.4081232 | I33: =+'Tata-input'!I17/(('Tata-input'!H62+'Tata-input'!I62)/2) -> 1.4895682 | J33: =+'Tata-input'!J17/(('Tata-input'!I62+'Tata-input'!J62)/2) -> 1.6643444 | K33: =+'Tata-input'!K17/(('Tata-input'!J62+'Tata-input'!K62)/2) -> 1.7498084
A34: Receivables days (Low is better) | C34: =365/('Tata-input'!C17/AVERAGE('Tata-input'!B67:C67)) -> 55.366285 | D34: =365/('Tata-input'!D17/AVERAGE('Tata-input'!C67:D67)) -> 58.095343 | E34: =365/('Tata-input'!E17/AVERAGE('Tata-input'!D67:E67)) -> 60.321326 | F34: =365/('Tata-input'!F17/AVERAGE('Tata-input'!E67:F67)) -> 65.40113 | G34: =365/('Tata-input'!G17/AVERAGE('Tata-input'!F67:G67)) -> 66.265032 | H34: =365/('Tata-input'!H17/AVERAGE('Tata-input'!G67:H67)) -> 62.290301 | I34: =365/('Tata-input'!I17/AVERAGE('Tata-input'!H67:I67)) -> 56.631128 | J34: =365/('Tata-input'!J17/AVERAGE('Tata-input'!I67:J67)) -> 54.39849 | K34: =365/('Tata-input'!K17/AVERAGE('Tata-input'!J67:K67)) -> 56.514214
A35: Inventory Turnover (High is better) | C35: ='Tata-input'!C17/(AVERAGE('Tata-input'!B68:C68)) -> 700.44693 | D35: ='Tata-input'!D17/(AVERAGE('Tata-input'!C68:D68)) -> 789.76827 | E35: ='Tata-input'!E17/(AVERAGE('Tata-input'!D68:E68)) -> 726.20437 | F35: ='Tata-input'!F17/(AVERAGE('Tata-input'!E68:F68)) -> 319.10688 | G35: ='Tata-input'!G17/(AVERAGE('Tata-input'!F68:G68)) -> 228.25797 | H35: ='Tata-input'!H17/(AVERAGE('Tata-input'!G68:H68)) -> 318.40797 | I35: ='Tata-input'!I17/(AVERAGE('Tata-input'!H68:I68)) -> 462.52019 | J35: ='Tata-input'!J17/(AVERAGE('Tata-input'!I68:J68)) -> 180.29371 | K35: ='Tata-input'!K17/(AVERAGE('Tata-input'!J68:K68)) -> 172.20021
A36: Working capital cycle days (Rec + Inv Days) | C36: =+C34+365/C35 -> 55.887381 | D36: =+D34+365/D35 -> 58.557503 | E36: =+E34+365/E35 -> 60.823939 | F36: =+F34+365/F35 -> 66.544947 | G36: =+G34+365/G35 -> 67.8641 | H36: =+H34+365/H35 -> 63.436629 | I36: =+I34+365/I35 -> 57.420283 | J36: =+J34+365/J35 -> 56.422964 | K36: =+K34+365/K35 -> 58.633839
A38: Net Fixed Assets (NFA) | B38: =+'Tata-input'!B62 -> 14703.82 | C38: =+'Tata-input'!C62 -> 14443.81 | D38: =+'Tata-input'!D62 -> 10928.51 | E38: =+'Tata-input'!E62 -> 10796.54 | F38: =+'Tata-input'!F62 -> 11289.39 | G38: =+'Tata-input'!G62 -> 12768.18 | H38: =+'Tata-input'!H62 -> 11519.61 | I38: =+'Tata-input'!I62 -> 10936.2 | ... K38: =+'Tata-input'!K62 -> 13467.41
A39: Capital Work in Progress (CWIP) | B39: =+'Tata-input'!B63 -> 638.34 | C39: =+'Tata-input'!C63 -> 799.82 | D39: =+'Tata-input'!D63 -> 750.92 | E39: =+'Tata-input'!E63 -> 520.31 | F39: =+'Tata-input'!F63 -> 361.34 | G39: =+'Tata-input'!G63 -> 348.86 | H39: =+'Tata-input'!H63 -> 492.92 | I39: =+'Tata-input'!I63 -> 852.46 | ... K39: =+'Tata-input'!K63 -> 1327.03
A41: Dividend Paid (Div) Without DDT | B41: =+'Tata-input'!B31 -> 156.75 | C41: =+'Tata-input'!C31 -> 122.55 | D41: =+'Tata-input'!D31 -> 171 | E41: =+'Tata-input'!E31 -> 128.25 | F41: =+'Tata-input'!F31 -> 128.25 | G41: =+'Tata-input'!G31 -> 114 | H41: =+'Tata-input'!H31 -> 399 | I41: =+'Tata-input'!I31 -> 589.95 | ... K41: =+'Tata-input'!K31 -> 475.95 | M41: =+SUM(B41:K41) -> 2884.2 | N41: Div Growth | O41: =IF(B41=0,"",POWER($K41/B41,1/9)-1) -> 0.13134449 | P41: =IF(D41=0,"",POWER($K41/D41,1/7)-1) -> 0.15746886 | Q41: =IF(F41=0,"",POWER($K41/F41,1/5)-1) -> 0.29987261 | R41: =IF(H41=0,"",POWER($K41/H41, 1/3)-1) -> 0.060545922 | S41: =IF(ISERROR(MAX(IF(J41=0,"",(K41-J41)/J41),IF(K41=0,"",(#REF!-K41)/K41))),"",MAX(IF(J41=0,"",(K41-J41)/J41),IF(K41=0,"",(#REF!-K41)/K41)))
A42: Dividend Payout (Div/PAT) | B42: =+'Tata-input'!B31/'Tata-input'!B30 -> 121.51163 | C42: =+'Tata-input'!C31/'Tata-input'!C30 -> 14.118664 | D42: =+'Tata-input'!D31/'Tata-input'!D30 -> 0.13870076 | E42: =+'Tata-input'!E31/'Tata-input'!E30 -> -0.39029215 | F42: =+'Tata-input'!F31/'Tata-input'!F30 -> -1.5569989 | G42: =+'Tata-input'!G31/'Tata-input'!G30 -> -1.3261982 | H42: =+'Tata-input'!H31/'Tata-input'!H30 -> 0.3190392 | I42: =+'Tata-input'!I31/'Tata-input'!I30 -> 0.3981414 | ... K42: =+'Tata-input'!K31/'Tata-input'!K30 -> 0.49151125
A43: Retained Earnings (RE=PAT-Div) | B43: =+'Tata-input'!B30-'Tata-input'!B31 -> -155.46 | C43: =+'Tata-input'!C30-'Tata-input'!C31 -> -113.87 | D43: =+'Tata-input'!D30-'Tata-input'!D31 -> 1061.87 | E43: =+'Tata-input'!E30-'Tata-input'!E31 -> -456.85 | F43: =+'Tata-input'!F30-'Tata-input'!F31 -> -210.62 | G43: =+'Tata-input'!G30-'Tata-input'!G31 -> -199.96 | H43: =+'Tata-input'!H30-'Tata-input'!H31 -> 851.63 | I43: =+'Tata-input'!I30-'Tata-input'!I31 -> 891.81 | ... K43: =+'Tata-input'!K30-'Tata-input'!K31 -> 492.39
A44: Price to earning | B44: =IF(+B45/B13<=0,0,B45/B13) -> 5821.5116 | C44: =IF(+C45/C13<=0,0,C45/C13) -> 774.16244 | D44: =IF(+D45/D13<=0,0,D45/D13) -> 10.422437 | E44: =IF(+E45/E13<=0,0,E45/E13) -> 0 | F44: =IF(+F45/F13<=0,0,F45/F13) -> 0 | G44: =IF(+G45/G13<=0,0,G45/G13) -> 0 | H44: =IF(+H45/H13<=0,0,H45/H13) -> 24.219633 | I44: =IF(+I45/I13<=0,0,I45/I13) -> 23.63075 | ... K44: =IF(+K45/K13<=0,0,K45/K13) -> 59.169713
...

Sheet Highlights 
B3: Acquiring Company Financials | I3: Target Company Financials
B4: Parameter | C4: 10-Year | D4: 7-Year | E4: 5-Year | F4: 3-Year | I4: Parameter | J4: 10-Year | K4: 7-Year | L4: 5-Year | M4: 3-Year
B5: Sales Growth | C5: 0.0667 | D5: 0.1317 | E5: 0.1423 | F5: 0.0848 | I5: Sales Growth | J5: 0.0058 | K5: 0.0252 | L5: 0.0488 | M5: 0.0703
B6: Operating Profit Margin (OPM%) | C6: 0.4554 | D6: 0.4867 | E6: 0.5105 | F6: 0.5256 | I6: Operating Profit Margin (OPM%) | J6: 0.1865 | K6: 0.2072 | L6: 0.2266 | M6: 0.23
B7: PAT Growth (Profit After Tax) | C7: 0.1013 | D7: 0.7872 | E7: -1.7911 | F7: 2.2953 | I7: PAT Growth (Profit After Tax) | J7: 1.0869 | K7: -0.0339 | L7: -2.637 | M7: -0.0817
B10: Key Parameters | C10: AIRTEL | D10: TATACOMM
B11: ROCE | C11: 0.131 | D11: 0.176
B12: ROE | C12: 0.149 | D12: 0.652
B13: EPS | C13: 43.2 | D13: 39.2
B14: EVEBITDA | C14: 12.6 | D14: 10.7
B15: Market Capitalization in Cr. | C15: =942786 -> 942786 | D15: =37513 -> 37513
D19: 17.6 %
D20: ROE65.2 %

Sheet WACC Calc
B1: Airtel
B2: Revenue by Geography | C2: 2017 | D2: 2018 | E2: 2019 | F2: 2020 | G2: 2021 | H2: 2022 | I2: 2023
B3: India | C3: 0.687 | D3: 0.648 | E3: 0.648 | F3: 0.652 | G3: 0.639 | H3: 0.639 | I3: 0.67
B4: Africa | C4: 0.306 | D4: 0.345 | E4: 0.346 | F4: 0.343 | G4: 0.359 | H4: 0.359 | I4: 0.328
B5: South Asia | C5: 0.006 | D5: 0.007 | E5: 0.006 | F5: 0.005 | G5: 0.004 | H5: 0.002 | I5: 0.003
B9: Region | C9: ERP | D9: Default Spread | E9: Weighted Average: Default Spreads | F9: Tax Rate | G9: Weighted Average: CRP | H9: Total GDP (in $ millions)
B10: Africa | C10: 0.10493974 | D10: 0.058347166 | E10: 0.061639737 | F10: 0.27421915 | G10: 0.083065163 | H10: 2508220.7
B11: Asia | C11: 0.054008616 | D11: 0.010802217 | E11: 0.010708616 | F11: 0.25344179 | G11: 0.0154 | H11: 32948678
B14: Country | C14: Moody's rating | D14: Adj. Default Spread | E14: Equity Risk Premium | F14: Country Risk Premium | G14: Corporate Tax Rate
B15: India | C15: Baa3 | D15: 0.021767594 | E15: 0.072646034 | F15: 0.029346034 | G15: 0.3
B18: ERP Calculation
B19: Revenue weighted ERP | C19: =C10*I4+C11*I5+E15*I3 -> 0.083255102
B21: Tata Communications
B22: ERP | C22: =E15 -> 0.072646034

Sheet Tata-input
A1: COMPANY NAME | B1: TATA COMMUNICATIONS LTD | E1: =IF(B2<>B3, "A NEW VERSION OF THE WORKSHEET IS AVAILABLE", "")
A2: LATEST VERSION | B2: 2.1 | E2: PLEASE DO NOT MAKE ANY CHANGES TO THIS SHEET
A3: CURRENT VERSION | B3: 2.1
A5: META
A6: Number of shares | B6: =IF(B9>0, B9/B8, 0) -> 28.5
A7: Face Value | B7: 10
A8: Current Price | B8: 1352.5
A9: Market Capitalization | B9: 38546.25
A15: PROFIT & LOSS
A16: Report Date | B16: 42094 | C16: 42460 | D16: 42825 | E16: 43190 | F16: 43555 | G16: 43921 | H16: 44286 | I16: 44651 | J16: 45016 | K16: 45382 | L16: 45747 | M16: 46112 | N16: 46477 | O16: 46843 | P16: 47208 | Q16: 47573
A17: Sales | B17: 19913.34 | C17: 18148.58 | D17: 17619.73 | E17: 16771.69 | F17: 16524.95 | G17: 17067.99 | H17: 17100.1 | I17: 16724.73 | J17: 17838.26 | K17: 20968.82
A18: Raw Material Cost
A19: Change in Inventory
A20: Power and Fuel | B20: 433.67 | C20: 252.04 | D20: 271 | E20: 253.75 | F20: 283.86 | G20: 293 | H20: 269.11 | I20: 273.02 | J20: 316.58 | K20: 355.84
A21: Other Mfr. Exp | B21: 11595.11 | C21: 10738.8 | D21: 10125.85 | E21: 9205.52 | F21: 8489 | G21: 8670.36 | H21: 8222.19 | I21: 7951.89 | J21: 8219.33 | K21: 10148.69
A22: Employee Cost | B22: 2809.35 | C22: 2739.56 | D22: 2839.41 | E22: 2977.52 | F22: 2959.66 | G22: 3039.14 | H22: 3049.09 | I22: 3040.34 | J22: 3597.46 | K22: 4452.95
A23: Selling and admin | B23: 1751.04 | C23: 1624.45 | D23: 1643.43 | E23: 1517.92 | F23: 1567.95 | G23: 1381.48 | H23: 973.68 | I23: 980.13 | J23: 1083.02 | K23: 1361.88
A24: Other Expenses | B24: 330.12 | C24: 359.49 | D24: 334.14 | E24: 404.76 | F24: 479.63 | G24: 395.06 | H24: 325.45 | I24: 252.63 | J24: 303.64 | K24: 419.36
A25: Other Income | B25: 291.24 | C25: 82.42 | D25: 1293.82 | E25: -115.86 | F25: 62.5 | G25: -320.83 | H25: 82.04 | I25: 338.05 | J25: 439.5 | K25: 46.81
A26: Depreciation | B26: 2161.09 | C26: 1864.29 | D26: 1865.77 | E26: 1906.3 | F26: 2067.6 | G26: 2357.72 | H26: 2313.87 | I26: 2204.54 | J26: 2261.81 | K26: 2469.67
A27: Interest | B27: 750.79 | C27: 409.06 | D27: 367.19 | E27: 344.45 | F27: 396.55 | G27: 470.74 | H27: 420.2 | I27: 360.25 | J27: 432.46 | K27: 644.15
A28: Profit before tax | B28: 373.41 | C28: 243.31 | D28: 1466.76 | E28: 45.61 | F28: 343.2 | G28: 139.66 | H28: 1608.55 | I28: 1999.98 | J28: 2063.46 | K28: 1163.09
A29: Tax | B29: 370.46 | C29: 232.85 | D29: 236.38 | E29: 354.92 | F29: 273.32 | G29: 226.67 | H29: 354.89 | I29: 522.13 | J29: 296.62 | K29: 213.5
A30: Net profit | B30: 1.29 | C30: 8.68 | D30: 1232.87 | E30: -328.6 | F30: -82.37 | G30: -85.96 | H30: 1250.63 | I30: 1481.76 | J30: 1795.96 | K30: 968.34
A31: Dividend Amount | B31: 156.75 | C31: 122.55 | D31: 171 | E31: 128.25 | F31: 128.25 | G31: 114 | H31: 399 | I31: 589.95 | J31: 598.5 | K31: 475.95
A40: Quarters
A41: Report Date | B41: 44834 | C41: 44926 | D41: 45016 | E41: 45107 | F41: 45199 | G41: 45291 | H41: 45382 | I41: 45473 | J41: 45565 | K41: 45657
A42: Sales | B42: 4430.74 | C42: 4528.34 | D42: 4568.66 | E42: 4771.36 | F42: 4872.5 | G42: 5587.78 | H42: 5691.7 | I42: 5633.37 | J42: 5727.85 | K42: 5798.07
A43: Expenses | B43: 3301.12 | C43: 3450.98 | D43: 3534.44 | E43: 3747.32 | F43: 3857.05 | G43: 4434.68 | H43: 4635.4 | I43: 4509.16 | J43: 4598.47 | K43: 4617.12
A44: Other Income | B44: 112.97 | C44: 30.75 | D44: 61.79 | E44: 190.6 | F44: 25.36 | G44: -211.88 | H44: 4.89 | I44: 112.05 | J44: 29.11 | K44: -6.85
A45: Depreciation | B45: 551.63 | C45: 554.82 | D45: 618.5 | E45: 579.74 | F45: 605.12 | G45: 603.01 | H45: 665.84 | I45: 647.37 | J45: 648.16 | K45: 637.14
A46: Interest | B46: 97.78 | C46: 122.67 | D46: 132.11 | E46: 131.03 | F46: 137.42 | G46: 184.46 | H46: 188.15 | I46: 172.2 | J46: 189.43 | K46: 186.89
A47: Profit before tax | B47: 593.18 | C47: 430.62 | D47: 345.4 | E47: 503.87 | F47: 298.27 | G47: 153.75 | H47: 207.2 | I47: 416.69 | J47: 320.9 | K47: 350.07
A48: Tax | B48: 65.85 | C48: 43.58 | D48: 28.05 | E48: 130.63 | F48: 77.88 | G48: 113.47 | H48: -108.48 | I48: 86.79 | J48: 97.62 | K48: 126.19
A49: Net profit | B49: 532.29 | C49: 393.88 | D49: 326.03 | E49: 381.69 | F49: 220.66 | G49: 44.81 | H49: 321.18 | I49: 332.84 | J49: 227.23 | K49: 235.96
A50: Operating Profit | B50: 1129.62 | C50: 1077.36 | D50: 1034.22 | E50: 1024.04 | F50: 1015.45 | G50: 1153.1 | H50: 1056.3 | I50: 1124.21 | J50: 1129.38 | K50: 1180.95
A55: BALANCE SHEET
A56: Report Date | B56: 42094 | C56: 42460 | D56: 42825 | E56: 43190 | F56: 43555 | G56: 43921 | H56: 44286 | I56: 44651 | J56: 45016 | K56: 45382
A57: Equity Share Capital | B57: 285 | C57: 285 | D57: 285 | E57: 285 | F57: 285 | G57: 285 | H57: 285 | I57: 285 | J57: 285 | K57: 285
A58: Reserves | B58: 36.47 | C58: -648.36 | D58: 1306.9 | E58: 214.32 | F58: -466.81 | G58: -1563.36 | H58: -169.54 | I58: 642.59 | J58: 1233.26 | K58: 1501.42
...

Sheet Airtel
A1: (₹ Crores/10 Millions) | D1: =+'Airtel-input'!B1 -> BHARTI AIRTEL LTD | L1: =+'Airtel-input'!K41 -> 45657 | M1: << Latest available quarterly results
A2: Narration | B2: =+'Airtel-input'!B16 -> 42094 | C2: =+'Airtel-input'!C16 -> 42460 | D2: =+'Airtel-input'!D16 -> 42825 | E2: =+'Airtel-input'!E16 -> 43190 | F2: =+'Airtel-input'!F16 -> 43555 | G2: =+'Airtel-input'!G16 -> 43921 | H2: =+'Airtel-input'!H16 -> 44286 | I2: =+'Airtel-input'!I16 -> 44651 | ... K2: =+'Airtel-input'!K16 -> 45382 | L2: Last 4 Quarters | M2: Total 10 Yrs | N2: TRENDS: | O2: 10Yr | P2: 7Yr | Q2: 5Yr | R2: 3Yr | S2: TTM
A3: Sales | B3: =+'Airtel-input'!B17 -> 96100.7 | C3: =+'Airtel-input'!C17 -> 96532.1 | D3: =+'Airtel-input'!D17 -> 95468.3 | E3: =+'Airtel-input'!E17 -> 82638.8 | F3: =+'Airtel-input'!F17 -> 80780.2 | G3: =+'Airtel-input'!G17 -> 87539 | H3: =+'Airtel-input'!H17 -> 100615.8 | I3: =+'Airtel-input'!I17 -> 116546.9 | ... K3: =+'Airtel-input'!K17 -> 149982.4 | L3: =IF(N66=TRUE,"",SUM('Airtel-input'!H42:K42)) -> 162708.1 | N3: Sales Growth | O3: =IF(B3=0,"",POWER($K3/B3,1/9)-1) -> 0.050701386 | P3: =IF(D3=0,"",POWER($K3/D3,1/7)-1) -> 0.066659665 | Q3: =IF(F3=0,"",POWER($K3/F3,1/5)-1) -> 0.13174107 | R3: =IF(H3=0,"",POWER($K3/H3, 1/3)-1) -> 0.14232944 | S3: =IF(N66=TRUE,"",L3/K3-1) -> 0.084847955
A4: Operating Profit | B4: =+'Airtel-input'!B17-'Airtel-input'!B18+'Airtel-input'!B19-SUM('Airtel-input'!B20:B24) -> 33602 | C4: =+'Airtel-input'!C17-'Airtel-input'!C18+'Airtel-input'!C19-SUM('Airtel-input'!C20:C24) -> 33984.2 | D4: =+'Airtel-input'!D17-'Airtel-input'!D18+'Airtel-input'!D19-SUM('Airtel-input'!D20:D24) -> 35329.8 | E4: =+'Airtel-input'!E17-'Airtel-input'!E18+'Airtel-input'!E19-SUM('Airtel-input'!E20:E24) -> 30079.1 | F4: =+'Airtel-input'!F17-'Airtel-input'!F18+'Airtel-input'!F19-SUM('Airtel-input'!F20:F24) -> 25763.8 | G4: =+'Airtel-input'!G17-'Airtel-input'!G18+'Airtel-input'!G19-SUM('Airtel-input'!G20:G24) -> 36609.5 | H4: =+'Airtel-input'!H17-'Airtel-input'!H18+'Airtel-input'!H19-SUM('Airtel-input'!H20:H24) -> 45278.9 | I4: =+'Airtel-input'!I17-'Airtel-input'!I18+'Airtel-input'!I19-SUM('Airtel-input'!I20:I24) -> 57533.9 | ... K4: =+'Airtel-input'!K17-'Airtel-input'!K18+'Airtel-input'!K19-SUM('Airtel-input'!K20:K24) -> 78291.8 | L4: =+IF(N66=TRUE,"",SUM('Airtel-input'!H50:K50)) -> 85515.2 | N4: OPM | O4: =IF(SUM(B3:$K$3)=0,"",SUMPRODUCT(B5:$K$5,B3:$K$3)/SUM(B3:$K$3)) -> 0.4283225 | P4: =IF(SUM(E3:$K$3)=0,"",SUMPRODUCT(E5:$K$5,E3:$K$3)/SUM(E3:$K$3)) -> 0.45537333 | Q4: =IF(SUM(G3:$K$3)=0,"",SUMPRODUCT(G5:$K$5,G3:$K$3)/SUM(G3:$K$3)) -> 0.48665129 | R4: =IF(SUM(I3:$K$3)=0, "", SUMPRODUCT(I5:$K$5,I3:$K$3)/SUM(I3:$K$3)) -> 0.51050634 | S4: =IF(N66=TRUE,"",L5) -> 0.52557433
A5: Operating Profit Margin (OPM%) | B5: =IF(B4>0,B4/B3,0) -> 0.34965406 | C5: =IF(C4>0,C4/C3,0) -> 0.35205077 | D5: =IF(D4>0,D4/D3,0) -> 0.37006839 | E5: =IF(E4>0,E4/E3,0) -> 0.36398278 | F5: =IF(F4>0,F4/F3,0) -> 0.31893707 | G5: =IF(G4>0,G4/G3,0) -> 0.41820788 | H5: =IF(H4>0,H4/H3,0) -> 0.45001779 | I5: =IF(I4>0,I4/I3,0) -> 0.49365449 | ... K5: =IF(K4>0,K4/K3,0) -> 0.52200658 | L5: =+IF(N66=TRUE,"",IF(L4>0,L4/L3,0)) -> 0.52557433 | N5: PAT Growth | O5: =IF(B13=0,"",POWER($K13/B13,1/9)-1) -> 0.054772445 | P5: =IF(D13=0,"",POWER($K13/D13,1/7)-1) -> 0.10131664 | Q5: =IF(F13=0,"",POWER($K13/F13,1/5)-1) -> 0.78722178 | R5: =IF(H13=0,"",POWER($K13/H13, 1/3)-1) -> -1.7910696 | S5: =+IF(N66=TRUE,"",L13/K13-1) -> 2.2952859
A6: Other Income | B6: =+'Airtel-input'!B25 -> 1242.6 | C6: =+'Airtel-input'!C25 -> 4858 | D6: =+'Airtel-input'!D25 -> 1713.1 | E6: =+'Airtel-input'!E25 -> 1756.5 | F6: =+'Airtel-input'!F25 -> 4474.1 | G6: =+'Airtel-input'!G25 -> -37774.6 | H6: =+'Airtel-input'!H25 -> -4215 | I6: =+'Airtel-input'!I25 -> 4656.1 | ... K6: =+'Airtel-input'!K25 -> -3427.5 | L6: =IF(N66=TRUE,"",+SUM('Airtel-input'!H44:K44)) -> 10851.8 | M6: =SUM(B6:K6) -> -25697.8 | N6: Avg. PE | O6: =IF(ISERROR(AVERAGEIF(B44:$L44,">0")),"",AVERAGEIF(B44:$L44,">0")) -> 118.33481 | P6: =IF(ISERROR(AVERAGEIF(E44:$L44,">0")),"",AVERAGEIF(E44:$L44,">0")) -> 166.0525 | Q6: =IF(ISERROR(AVERAGEIF(G44:$L44,">0")),"",AVERAGEIF(G44:$L44,">0")) -> 82.495533 | R6: =IF(ISERROR(AVERAGEIF(I44:$L44,">0")),"",AVERAGEIF(I44:$L44,">0")) -> 82.495533 | S6: =IF(N66=TRUE,"",O10) -> 38.165938
A7: EBITDA | B7: =+SUM(B4+B6) -> 34844.6 | C7: =+SUM(C4+C6) -> 38842.2 | D7: =+SUM(D4+D6) -> 37042.9 | E7: =+SUM(E4+E6) -> 31835.6 | F7: =+SUM(F4+F6) -> 30237.9 | G7: =+SUM(G4+G6) -> -1165.1 | H7: =+SUM(H4+H6) -> 41063.9 | I7: =+SUM(I4+I6) -> 62190 | ... K7: =+SUM(K4+K6) -> 74864.3 | L7: =++IF(N66=TRUE,"",SUM(L4+L6)) -> 96367 | M7: =SUM(B7:K7) -> 422048.7
A8: Interest | B8: =+'Airtel-input'!B27 -> 4446.5 | C8: =+'Airtel-input'!C27 -> 8546.1 | D8: =+'Airtel-input'!D27 -> 9546.6 | E8: =+'Airtel-input'!E27 -> 9325.5 | F8: =+'Airtel-input'!F27 -> 10622.2 | G8: =+'Airtel-input'!G27 -> 13991.8 | H8: =+'Airtel-input'!H27 -> 15091 | I8: =+'Airtel-input'!I27 -> 16616.2 | ... K8: =+'Airtel-input'!K27 -> 22647.7 | L8: =+IF(N66=TRUE,"",SUM('Airtel-input'!H46:K46)) -> 21454.9 | M8: =SUM(B8:K8) -> 130133.5
A9: Depreciation | B9: =+'Airtel-input'!B26 -> 19858.3 | C9: =+'Airtel-input'!C26 -> 17449.8 | D9: =+'Airtel-input'!D26 -> 19773 | E9: =+'Airtel-input'!E26 -> 19243.1 | F9: =+'Airtel-input'!F26 -> 21347.5 | G9: =+'Airtel-input'!G26 -> 27689.6 | H9: =+'Airtel-input'!H26 -> 29404.4 | I9: =+'Airtel-input'!I26 -> 33090.7 | ... K9: =+'Airtel-input'!K26 -> 39537.6 | L9: =IF(N66=TRUE,"",+SUM('Airtel-input'!H45:K45)) -> 43319.5 | M9: =SUM(B9:K9) -> 263825.8 | N9: CMP | O9: =+'Airtel-input'!B8 -> 1570.2
A10: Profit before tax (PBT) | B10: =+'Airtel-input'!B28 -> 10539.8 | C10: =+'Airtel-input'!C28 -> 12846.3 | D10: =+'Airtel-input'!D28 -> 7723.3 | E10: =+'Airtel-input'!E28 -> 3267 | F10: =+'Airtel-input'!F28 -> -1731.8 | G10: =+'Airtel-input'!G28 -> -42846.5 | H10: =+'Airtel-input'!H28 -> -3431.5 | I10: =+'Airtel-input'!I28 -> 12483.1 | ... K10: =+'Airtel-input'!K28 -> 12679 | L10: =IF(N66=TRUE,"",+SUM('Airtel-input'!H47:K47)) -> 31592.6 | N10: P/E | O10: =IF(N66=TRUE,O15/K13,O15/L13) -> 38.165938
A11: Tax | B11: =+'Airtel-input'!B29 -> 5486.7 | C11: =+'Airtel-input'!C29 -> 5953.3 | D11: =+'Airtel-input'!D29 -> 3481.9 | E11: =+'Airtel-input'!E29 -> 1083.5 | F11: =+'Airtel-input'!F29 -> -3419.3 | G11: =+'Airtel-input'!G29 -> -12182.3 | H11: =+'Airtel-input'!H29 -> 8932.5 | I11: =+'Airtel-input'!I29 -> 4177.9 | ... K11: =+'Airtel-input'!K29 -> 4121 | L11: =IF(N66=TRUE,"",+SUM('Airtel-input'!H48:K48)) -> 4518.9
A12: Tax% | B12: =B11/B10 -> 0.52056965 | C12: =C11/C10 -> 0.46342527 | D12: =D11/D10 -> 0.4508306 | E12: =E11/E10 -> 0.33164983 | F12: =F11/F10 -> 1.9744197 | G12: =G11/G10 -> 0.28432427 | H12: =H11/H10 -> -2.603089 | I12: =I11/I10 -> 0.33468449 | ... K12: =K11/K10 -> 0.32502563 | L12: =+IF(N66=TRUE,"",L11/L10) -> 0.14303666 | N12: P/B | O12: =+'Airtel-input'!B9/SUM('Airtel-input'!K57:K58) -> 11.449902
A13: Net profit after tax (PAT) | B13: =+'Airtel-input'!B30 -> 4620.8 | C13: =+'Airtel-input'!C30 -> 6076.7 | D13: =+'Airtel-input'!D30 -> 3799.8 | E13: =+'Airtel-input'!E30 -> 1099 | F13: =+'Airtel-input'!F30 -> 409.5 | G13: =+'Airtel-input'!G30 -> -32183.2 | H13: =+'Airtel-input'!H30 -> -15083.5 | I13: =+'Airtel-input'!I30 -> 4254.9 | ... K13: =+'Airtel-input'!K30 -> 7467 | L13: =IF(N66=TRUE,"",+SUM('Airtel-input'!H49:K49)) -> 24605.9 | M13: =SUM(B13:K13) -> -11193.1 | N13: P/E*P/B | O13: =O10*O12 -> 436.99626
A14: Net Profit Margin (NPM%) | B14: =B13/B3 -> 0.048082896 | C14: =C13/C3 -> 0.062950045 | D14: =D13/D3 -> 0.039801693 | E14: =E13/E3 -> 0.013298838 | F14: =F13/F3 -> 0.0050693115 | G14: =G13/G3 -> -0.36764414 | H14: =H13/H3 -> -0.14991184 | I14: =I13/I3 -> 0.03650805 | ... K14: =K13/K3 -> 0.049785842 | L14: =+IF(N66=TRUE,"",L13/L3) -> 0.15122726 | N14: Div Yield | O14: ='Airtel-input'!K31/'Airtel-input'!B9 -> 0.0049009951
A15: Cash from Operating Activity (CFO) | B15: =+'Airtel-input'!B82 -> 28059 | C15: =+'Airtel-input'!C82 -> 27942.3 | D15: =+'Airtel-input'!D82 -> 28279.9 | E15: =+'Airtel-input'!E82 -> 29853.8 | F15: =+'Airtel-input'!F82 -> 20070.2 | G15: =+'Airtel-input'!G82 -> 18128.7 | H15: =+'Airtel-input'!H82 -> 48205 | I15: =+'Airtel-input'!I82 -> 55016.6 | ... K15: =+'Airtel-input'!K82 -> 78898.2 | L15: CFO | M15: =SUM(B15:K15) -> 399778.3 | N15: Market Cap | O15: =+'Airtel-input'!B9 -> 939107.25
A16: Capex {(NFA+WIP) change+Dep} | C16: =+'Airtel-input'!C62+'Airtel-input'!C63-'Airtel-input'!B62-'Airtel-input'!B63+'Airtel-input'!C26 -> 53751.2 | D16: =+'Airtel-input'!D62+'Airtel-input'!D63-'Airtel-input'!C62-'Airtel-input'!C63+'Airtel-input'!D26 -> 30851.8 | E16: =+'Airtel-input'!E62+'Airtel-input'!E63-'Airtel-input'!D62-'Airtel-input'!D63+'Airtel-input'!E26 -> 27121.1 | F16: =+'Airtel-input'!F62+'Airtel-input'!F63-'Airtel-input'!E62-'Airtel-input'!E63+'Airtel-input'!F26 -> 34861.6 | G16: =+'Airtel-input'!G62+'Airtel-input'!G63-'Airtel-input'!F62-'Airtel-input'!F63+'Airtel-input'!G26 -> 50761.7 | H16: =+'Airtel-input'!H62+'Airtel-input'!H63-'Airtel-input'!G62-'Airtel-input'!G63+'Airtel-input'!H26 -> 25072.7 | I16: =+'Airtel-input'!I62+'Airtel-input'!I63-'Airtel-input'!H62-'Airtel-input'!H63+'Airtel-input'!I26 -> 53922.6 | J16: =+'Airtel-input'!J62+'Airtel-input'!J63-'Airtel-input'!I62-'Airtel-input'!I63+'Airtel-input'!J26 -> 113213 | K16: =+'Airtel-input'!K62+'Airtel-input'!K63-'Airtel-input'!J62-'Airtel-input'!J63+'Airtel-input'!K26 -> 32925.6 | L16: Capex | M16: =SUM(B16:K16) -> 422481.3
A17: FCF | C17: =+C15-C16 -> -25808.9 | D17: =+D15-D16 -> -2571.9 | E17: =+E15-E16 -> 2732.7 | F17: =+F15-F16 -> -14791.4 | G17: =+G15-G16 -> -32633 | H17: =+H15-H16 -> 23132.3 | I17: =+I15-I16 -> 1094 | J17: =+J15-J16 -> -47888.4 | K17: =+K15-K16 -> 45972.6 | L17: FCF | M17: =+M15-M16 -> -22703 | N17: =SUM(B43:K43) -> -26449.41 | O17: Total Retained Earnings (RE) in 10 Yrs (A)
A18: Total Debt (D) | B18: =+'Airtel-input'!B59 -> 83415.1 | C18: =+'Airtel-input'!C59 -> 100646.5 | D18: =+'Airtel-input'!D59 -> 107287.6 | E18: =+'Airtel-input'!E59 -> 111333.5 | F18: =+'Airtel-input'!F59 -> 125428.3 | G18: =+'Airtel-input'!G59 -> 148228.1 | H18: =+'Airtel-input'!H59 -> 162785.2 | I18: =+'Airtel-input'!I59 -> 169677.9 | ... K18: =+'Airtel-input'!K59 -> 215592.3 | L18: FCFE (Post Int. exp.) | M18: =+M17-M8 -> -152836.5 | N18: =L45-IF(N21>0,N21*'Airtel-input'!B6,B45) -> 744242.86 | O18: Total increase in Mcap in 10 yrs (B)
A19: Share Capital | B19: =+'Airtel-input'!B57 -> 1998.7 | C19: =+'Airtel-input'!C57 -> 1998.7 | D19: =+'Airtel-input'!D57 -> 1998.7 | E19: =+'Airtel-input'!E57 -> 1998.7 | F19: =+'Airtel-input'!F57 -> 1998.7 | G19: =+'Airtel-input'!G57 -> 2727.8 | H19: =+'Airtel-input'!H57 -> 2746 | I19: =+'Airtel-input'!I57 -> 2795 | ... K19: =+'Airtel-input'!K57 -> 2876.6 | L19: Total Div 10 Yrs | M19: =+SUM(B41:K41) -> 15256.31 | N19: =N18/N17 -> -28.138354 | O19: Value created per INR of RE (B/A)
A20: Dividend Paid (Div) Without DDT | B20: =+'Airtel-input'!B31 -> 1539 | C20: =+'Airtel-input'!C31 -> 543.65 | D20: =+'Airtel-input'!D31 -> 399.74 | E20: =+'Airtel-input'!E31 -> 2134.61 | F20: =+'Airtel-input'!F31 -> 999.35 | G20: =+'Airtel-input'!G31 -> 1091.12 | H20: =+'Airtel-input'!H31 -> 0 | I20: =+'Airtel-input'!I31 -> 1677 | ... K20: =+'Airtel-input'!K31 -> 4602.56 | L20: Inc. in Debt in 10Yrs | M20: =+K18-B18 -> 132177.2
A21: Cash + Investments (CI +NCI) | B21: =+'Airtel-input'!B64+'Airtel-input'!B69 -> 12835.1 | C21: =+'Airtel-input'!C64+'Airtel-input'!C69 -> 17075.7 | D21: =+'Airtel-input'!D64+'Airtel-input'!D69 -> 19437 | E21: =+'Airtel-input'!E64+'Airtel-input'!E69 -> 22829.2 | F21: =+'Airtel-input'!F64+'Airtel-input'!F69 -> 23775 | G21: =+'Airtel-input'!G64+'Airtel-input'!G69 -> 41369.2 | H21: =+'Airtel-input'!H64+'Airtel-input'!H69 -> 41016.5 | I21: =+'Airtel-input'!I64+'Airtel-input'!I69 -> 42843.4 | ... K21: =+'Airtel-input'!K64+'Airtel-input'!K69 -> 47942.2 | L21: Cash+Investments | M21: =+K21 -> 47942.2 | N21: 0 | O21: Closing share price on March 31, 10 years back
A22: Net Debt | B22: =B18-B60 -> 81332 | C22: =C18-C60 -> 95547.8 | D22: =D18-D60 -> 102189.3 | E22: =E18-E60 -> 104662.9 | F22: =F18-F60 -> 117364.3 | G22: =G18-G60 -> 132335.4 | H22: =H18-H60 -> 149319.1 | I22: =I18-I60 -> 156183.6 | ... K22: =K18-K60 -> 199252.4 | L22: FCF/CFO | M22: =+M17/M15 -> -0.056788975
A23: Self-Sustainable Growth Rate (SSGR) | E23: =AVERAGE(C33:E33)*AVERAGE(C14:E14)*(1-AVERAGE(C42:E42))-AVERAGE(C66:E66) -> -0.098890956 | F23: =AVERAGE(D33:F33)*AVERAGE(D14:F14)*(1-AVERAGE(D42:F42))-AVERAGE(D66:F66) -> -0.11120653 | G23: =AVERAGE(E33:G33)*AVERAGE(E14:G14)*(1-AVERAGE(E42:G42))-AVERAGE(E66:G66) -> -0.087697271 | H23: =AVERAGE(F33:H33)*AVERAGE(F14:H14)*(1-AVERAGE(F42:H42))-AVERAGE(F66:H66) -> -0.13383352 | I23: =AVERAGE(G33:I33)*AVERAGE(G14:I14)*(1-AVERAGE(G42:I42))-AVERAGE(G66:I66) -> -0.19280584 | J23: =AVERAGE(H33:J33)*AVERAGE(H14:J14)*(1-AVERAGE(H42:J42))-AVERAGE(H66:J66) -> -0.13964698 | K23: =AVERAGE(I33:K33)*AVERAGE(I14:K14)*(1-AVERAGE(I42:K42))-AVERAGE(I66:K66) -> -0.1180102 | L23: Interest Outgo | M23: =+M52 -> 156109.33
L24: Change in 10 Yrs
A25: Trade Receivables | B25: =+'Airtel-input'!B67 -> 5207.2 | C25: =+'Airtel-input'!C67 -> 5503.9 | D25: =+'Airtel-input'!D67 -> 4740.2 | E25: =+'Airtel-input'!E67 -> 5883 | F25: =+'Airtel-input'!F67 -> 4300.6 | G25: =+'Airtel-input'!G67 -> 4605.8 | H25: =+'Airtel-input'!H67 -> 3637.7 | I25: =+'Airtel-input'!I67 -> 4056.2 | ... K25: =+'Airtel-input'!K67 -> 4727.7 | L25: =+B25-K25 -> 479.5
A26: Inventory | B26: =+'Airtel-input'!B68 -> 133.9 | C26: =+'Airtel-input'!C68 -> 169.2 | D26: =+'Airtel-input'!D68 -> 48.8 | E26: =+'Airtel-input'!E68 -> 69.3 | F26: =+'Airtel-input'!F68 -> 88.4 | G26: =+'Airtel-input'!G68 -> 156.9 | H26: =+'Airtel-input'!H68 -> 266 | I26: =+'Airtel-input'!I68 -> 375 | ... K26: =+'Airtel-input'!K68 -> 363.9 | U26: =+B26-K26 -> -230
A28: PBT/Avg. NFA (<10%,>25%) | C28: =C10/(AVERAGE(B38:C38)) -> 0.086632089 | D28: =D10/(AVERAGE(C38:D38)) -> 0.044066678 | E28: =E10/(AVERAGE(D38:E38)) -> 0.017880036 | F28: =F10/(AVERAGE(E38:F38)) -> -0.0089260703 | G28: =G10/(AVERAGE(F38:G38)) -> -0.19924573 | H28: =H10/(AVERAGE(G38:H38)) -> -0.015158975 | I28: =I10/(AVERAGE(H38:I38)) -> 0.053396452 | J28: =J10/(AVERAGE(I38:J38)) -> 0.063514582 | K28: =K10/(AVERAGE(J38:K38)) -> 0.04366822
A29: ROE on Avg Equity (<7%,>25%) | C29: =C13/AVERAGE(B49:C49) -> 0.11406684 | D29: =D13/AVERAGE(C49:D49) -> 0.056618112 | E29: =E13/AVERAGE(D49:E49) -> 0.016044885 | F29: =F13/AVERAGE(E49:F49) -> 0.0058102991 | G29: =G13/AVERAGE(F49:G49) -> -0.4332483 | H29: =H13/AVERAGE(G49:H49) -> -0.22165727 | I29: =I13/AVERAGE(H49:I49) -> 0.067803389 | J29: =J13/AVERAGE(I49:J49) -> 0.11582101 | K29: =K13/AVERAGE(J49:K49) -> 0.093582159
A30: ROCE (EBIT on Avg CE/TA) (<10%,>35%) | C30: =(C10+C8)/AVERAGE('Airtel-input'!B61:C61) -> 0.10527471 | D30: =(D10+D8)/AVERAGE('Airtel-input'!C61:D61) -> 0.075613465 | E30: =(E10+E8)/AVERAGE('Airtel-input'!D61:E61) -> 0.05226803 | F30: =(F10+F8)/AVERAGE('Airtel-input'!E61:F61) -> 0.033962165 | G30: =(G10+G8)/AVERAGE('Airtel-input'!F61:G61) -> -0.091151154 | H30: =(H10+H8)/AVERAGE('Airtel-input'!G61:H61) -> 0.033146726 | I30: =(I10+I8)/AVERAGE('Airtel-input'!H61:I61) -> 0.082478169 | J30: =(J10+J8)/AVERAGE('Airtel-input'!I61:J61) -> 0.08901016 | K30: =(K10+K8)/AVERAGE('Airtel-input'!J61:K61) -> 0.079692417
A31: Incremental ROE 3Yr Rolling | E31: =+(E13-B13)/SUM(B43:D43) -> -0.29311913 | F31: =+(F13-C13)/SUM(C43:E43) -> -0.71759418 | G31: =+(G13-D13)/SUM(D43:F43) -> -20.276682 | H31: =+(H13-E13)/SUM(E43:G43) -> 0.46368487 | I31: =+(I13-F13)/SUM(F43:H43) -> -0.078561451 | J31: =+(J13-G13)/SUM(G43:I43) -> -0.88530299 | K31: =+(K13-H13)/SUM(H43:J43) -> -3.5076326
A33: Net Fixed Asset Turnover (High is better) | C33: =+'Airtel-input'!C17/(('Airtel-input'!B62+'Airtel-input'!C62)/2) -> 0.65098725 | D33: =+'Airtel-input'!D17/(('Airtel-input'!C62+'Airtel-input'!D62)/2) -> 0.54471156 | E33: =+'Airtel-input'!E17/(('Airtel-input'!D62+'Airtel-input'!E62)/2) -> 0.45227571 | F33: =+'Airtel-input'!F17/(('Airtel-input'!E62+'Airtel-input'!F62)/2) -> 0.41635855 | G33: =+'Airtel-input'!G17/(('Airtel-input'!F62+'Airtel-input'!G62)/2) -> 0.40707578 | H33: =+'Airtel-input'!H17/(('Airtel-input'!G62+'Airtel-input'!H62)/2) -> 0.44447979 | I33: =+'Airtel-input'!I17/(('Airtel-input'!H62+'Airtel-input'!I62)/2) -> 0.49852929 | J33: =+'Airtel-input'!J17/(('Airtel-input'!I62+'Airtel-input'!J62)/2) -> 0.53365642 | K33: =+'Airtel-input'!K17/(('Airtel-input'!J62+'Airtel-input'!K62)/2) -> 0.51656002
A34: Receivables days (Low is better) | C34: =365/('Airtel-input'!C17/AVERAGE('Airtel-input'!B67:C67)) -> 20.250008 | D34: =365/('Airtel-input'!D17/AVERAGE('Airtel-input'!C67:D67)) -> 19.582922 | E34: =365/('Airtel-input'!E17/AVERAGE('Airtel-input'!D67:E67)) -> 23.460336 | F34: =365/('Airtel-input'!F17/AVERAGE('Airtel-input'!E67:F67)) -> 23.006962 | G34: =365/('Airtel-input'!G17/AVERAGE('Airtel-input'!F67:G67)) -> 18.56793 | H34: =365/('Airtel-input'!H17/AVERAGE('Airtel-input'!G67:H67)) -> 14.952311 | I34: =365/('Airtel-input'!I17/AVERAGE('Airtel-input'!H67:I67)) -> 12.047826 | J34: =365/('Airtel-input'!J17/AVERAGE('Airtel-input'!I67:J67)) -> 10.542113 | K34: =365/('Airtel-input'!K17/AVERAGE('Airtel-input'!J67:K67)) -> 10.597437
A35: Inventory Turnover (High is better) | C35: ='Airtel-input'!C17/(AVERAGE('Airtel-input'!B68:C68)) -> 636.96536 | D35: ='Airtel-input'!D17/(AVERAGE('Airtel-input'!C68:D68)) -> 875.85596 | E35: ='Airtel-input'!E17/(AVERAGE('Airtel-input'!D68:E68)) -> 1399.4716 | F35: ='Airtel-input'!F17/(AVERAGE('Airtel-input'!E68:F68)) -> 1024.4794 | G35: ='Airtel-input'!G17/(AVERAGE('Airtel-input'!F68:G68)) -> 713.73013 | H35: ='Airtel-input'!H17/(AVERAGE('Airtel-input'!G68:H68)) -> 475.83731 | I35: ='Airtel-input'!I17/(AVERAGE('Airtel-input'!H68:I68)) -> 363.64087 | J35: ='Airtel-input'!J17/(AVERAGE('Airtel-input'!I68:J68)) -> 439.91401 | K35: ='Airtel-input'!K17/(AVERAGE('Airtel-input'!J68:K68)) -> 482.6465
A36: Working capital cycle days (Rec + Inv Days) | C36: =+C34+365/C35 -> 20.823037 | D36: =+D34+365/D35 -> 19.999657 | E36: =+E34+365/E35 -> 23.721149 | F36: =+F34+365/F35 -> 23.363241 | G36: =+G34+365/G35 -> 19.079327 | H36: =+H34+365/H35 -> 15.71938 | I36: =+I34+365/I35 -> 13.051563 | J36: =+J34+365/J35 -> 11.371821 | K36: =+K34+365/K35 -> 11.353684
N37: (Sales -(depreciation+Marketing exp + SG&A)-Interest)*(1-tax%) +depreciation - capex - NWC change
A38: Net Fixed Assets (NFA) | B38: =+'Airtel-input'!B62 -> 124278.6 | C38: =+'Airtel-input'!C62 -> 172292.8 | D38: =+'Airtel-input'!D62 -> 178235.1 | E38: =+'Airtel-input'!E62 -> 187200.4 | F38: =+'Airtel-input'!F62 -> 200831.5 | G38: =+'Airtel-input'!G62 -> 229255.5 | H38: =+'Airtel-input'!H62 -> 223479.6 | I38: =+'Airtel-input'!I62 -> 244083.3 | ... K38: =+'Airtel-input'!K62 -> 303303.1
A39: Capital Work in Progress (CWIP) | B39: =+'Airtel-input'!B63 -> 17414.8 | C39: =+'Airtel-input'!C63 -> 5702 | D39: =+'Airtel-input'!D63 -> 10838.5 | E39: =+'Airtel-input'!E63 -> 9751.2 | F39: =+'Airtel-input'!F63 -> 9634.2 | G39: =+'Airtel-input'!G63 -> 4282.3 | H39: =+'Airtel-input'!H63 -> 5726.5 | I39: =+'Airtel-input'!I63 -> 5954.7 | ... K39: =+'Airtel-input'!K63 -> 16904.1
A41: Dividend Paid (Div) Without DDT | B41: =+'Airtel-input'!B31 -> 1539 | C41: =+'Airtel-input'!C31 -> 543.65 | D41: =+'Airtel-input'!D31 -> 399.74 | E41: =+'Airtel-input'!E31 -> 2134.61 | F41: =+'Airtel-input'!F31 -> 999.35 | G41: =+'Airtel-input'!G31 -> 1091.12 | H41: =+'Airtel-input'!H31 -> 0 | I41: =+'Airtel-input'!I31 -> 1677 | ... K41: =+'Airtel-input'!K31 -> 4602.56 | M41: =+SUM(B41:K41) -> 15256.31 | N41: Div Growth | O41: =IF(B41=0,"",POWER($K41/B41,1/9)-1) -> 0.12943779 | P41: =IF(D41=0,"",POWER($K41/D41,1/7)-1) -> 0.41776131 | Q41: =IF(F41=0,"",POWER($K41/F41,1/5)-1) -> 0.35723912 | R41: =IF(H41=0,"",POWER($K41/H41, 1/3)-1) | S41: =IF(ISERROR(MAX(IF(J41=0,"",(K41-J41)/J41),IF(K41=0,"",(#REF!-K41)/K41))),"",MAX(IF(J41=0,"",(K41-J41)/J41),IF(K41=0,"",(#REF!-K41)/K41)))
A42: Dividend Payout (Div/PAT) | B42: =+'Airtel-input'!B31/'Airtel-input'!B30 -> 0.33305921 | C42: =+'Airtel-input'!C31/'Airtel-input'!C30 -> 0.089464677 | D42: =+'Airtel-input'!D31/'Airtel-input'!D30 -> 0.10520027 | E42: =+'Airtel-input'!E31/'Airtel-input'!E30 -> 1.9423203 | F42: =+'Airtel-input'!F31/'Airtel-input'!F30 -> 2.4404151 | G42: =+'Airtel-input'!G31/'Airtel-input'!G30 -> -0.033903403 | H42: =+'Airtel-input'!H31/'Airtel-input'!H30 -> 0 | I42: =+'Airtel-input'!I31/'Airtel-input'!I30 -> 0.39413382 | ... K42: =+'Airtel-input'!K31/'Airtel-input'!K30 -> 0.61638677
A43: Retained Earnings (RE=PAT-Div) | B43: =+'Airtel-input'!B30-'Airtel-input'!B31 -> 3081.8 | C43: =+'Airtel-input'!C30-'Airtel-input'!C31 -> 5533.05 | D43: =+'Airtel-input'!D30-'Airtel-input'!D31 -> 3400.06 | E43: =+'Airtel-input'!E30-'Airtel-input'!E31 -> -1035.61 | F43: =+'Airtel-input'!F30-'Airtel-input'!F31 -> -589.85 | G43: =+'Airtel-input'!G30-'Airtel-input'!G31 -> -33274.32 | H43: =+'Airtel-input'!H30-'Airtel-input'!H31 -> -15083.5 | I43: =+'Airtel-input'!I30-'Airtel-input'!I31 -> 2577.9 | ... K43: =+'Airtel-input'!K30-'Airtel-input'!K31 -> 2864.44
...

Sheet Airtel-input
A1: COMPANY NAME | B1: BHARTI AIRTEL LTD | E1: =IF(B2<>B3, "A NEW VERSION OF THE WORKSHEET IS AVAILABLE", "")
A2: LATEST VERSION | B2: 2.1 | E2: PLEASE DO NOT MAKE ANY CHANGES TO THIS SHEET
A3: CURRENT VERSION | B3: 2.1
A5: META
A6: Number of shares | B6: =IF(B9>0, B9/B8, 0) -> 598.0813
A7: Face Value | B7: 5
A8: Current Price | B8: 1570.2
A9: Market Capitalization | B9: 939107.25
A15: PROFIT & LOSS
A16: Report Date | B16: 42094 | C16: 42460 | D16: 42825 | E16: 43190 | F16: 43555 | G16: 43921 | H16: 44286 | I16: 44651 | J16: 45016 | K16: 45382
A17: Sales | B17: 96100.7 | C17: 96532.1 | D17: 95468.3 | E17: 82638.8 | F17: 80780.2 | G17: 87539 | H17: 100615.8 | I17: 116546.9 | J17: 139144.8 | K17: 149982.4
A18: Raw Material Cost | B18: 774.4
A19: Change in Inventory | B19: 494.8
A20: Power and Fuel | B20: 8439.8 | C20: 6904.9 | D20: 7294.6 | E20: 6908.2 | F20: 8043.6 | G20: 9124.9 | H20: 9224 | I20: 10489.8 | J20: 13088.2 | K20: 12636.9
A21: Other Mfr. Exp | B21: 30935.6 | C21: 34292.2 | D21: 34082.7 | E21: 30443.6 | F21: 31849.8 | G21: 29935.1 | H21: 34945.5 | I21: 35639.8 | J21: 34827.5 | K21: 36936.2
A22: Employee Cost | B22: 4857 | C22: 4910.8 | D22: 4303.2 | E22: 3977.1 | F22: 3797.5 | G22: 3807.2 | H22: 4114.6 | I22: 4433.3 | J22: 4830.8 | K22: 5323.1
A23: Selling and admin | B23: 16459.6 | C23: 10258.8 | D23: 8626.8 | E23: 6023.1 | F23: 5337.7 | G23: 4643.2 | H23: 4787.8 | I23: 6413.6 | J23: 8593.2 | K23: 9636.1
A24: Other Expenses | B24: 1527.1 | C24: 6181.2 | D24: 5831.2 | E24: 5207.7 | F24: 5987.8 | G24: 3419.1 | H24: 2265 | I24: 2036.5 | J24: 6531.6 | K24: 7158.3
A25: Other Income | B25: 1242.6 | C25: 4858 | D25: 1713.1 | E25: 1756.5 | F25: 4474.1 | G25: -37774.6 | H25: -4215 | I25: 4656.1 | J25: 1018.9 | K25: -3427.5
A26: Depreciation | B26: 19858.3 | C26: 17449.8 | D26: 19773 | E26: 19243.1 | F26: 21347.5 | G26: 27689.6 | H26: 29404.4 | I26: 33090.7 | J26: 36431.8 | K26: 39537.6
A27: Interest | B27: 4446.5 | C27: 8546.1 | D27: 9546.6 | E27: 9325.5 | F27: 10622.2 | G27: 13991.8 | H27: 15091 | I27: 16616.2 | J27: 19299.9 | K27: 22647.7
A28: Profit before tax | B28: 10539.8 | C28: 12846.3 | D28: 7723.3 | E28: 3267 | F28: -1731.8 | G28: -42846.5 | H28: -3431.5 | I28: 12483.1 | J28: 16560.7 | K28: 12679
A29: Tax | B29: 5486.7 | C29: 5953.3 | D29: 3481.9 | E29: 1083.5 | F29: -3419.3 | G29: -12182.3 | H29: 8932.5 | I29: 4177.9 | J29: 4273.3 | K29: 4121
A30: Net profit | B30: 4620.8 | C30: 6076.7 | D30: 3799.8 | E30: 1099 | F30: 409.5 | G30: -32183.2 | H30: -15083.5 | I30: 4254.9 | J30: 8345.9 | K30: 7467
A31: Dividend Amount | B31: 1539 | C31: 543.65 | D31: 399.74 | E31: 2134.61 | F31: 999.35 | G31: 1091.12 | I31: 1677 | J31: 2269.28 | K31: 4602.56
A40: Quarters
A41: Report Date | B41: 44834 | C41: 44926 | D41: 45016 | E41: 45107 | F41: 45199 | G41: 45291 | H41: 45382 | I41: 45473 | J41: 45565 | K41: 45657
A42: Sales | B42: 34526.8 | C42: 35804.4 | D42: 36009 | E42: 37440 | F42: 37043.8 | G42: 37899.5 | H42: 37599.1 | I42: 38506.4 | J42: 41473.3 | K42: 45129.3
A43: Expenses | B43: 16933 | C43: 17719.6 | D43: 17311.9 | E43: 17841.5 | F43: 17530.1 | G43: 18084.7 | H43: 18234.3 | I43: 18798.8 | J43: 19627.1 | K43: 20532.7
A44: Other Income | B44: 558.6 | C44: -412.2 | D44: 885.9 | E44: -2478.1 | F44: -653.9 | G44: 1012.8 | H44: -1308.3 | I44: 2010.2 | J44: 474.9 | K44: 9675
A45: Depreciation | B45: 8946.8 | C45: 9297.7 | D45: 9405.9 | E45: 9653.8 | F45: 9734.3 | G45: 10074.3 | H45: 10075.2 | I45: 10540.1 | J45: 11000 | K45: 11704.2
A46: Interest | B46: 4940.3 | C46: 4685.6 | D46: 5163.1 | E46: 5613.7 | F46: 5185.8 | G46: 6644.9 | H46: 5203.3 | I46: 5152.4 | J46: 5423.7 | K46: 5675.5
A47: Profit before tax | B47: 4265.3 | C47: 3689.3 | D47: 5014 | E47: 1852.9 | F47: 3939.7 | G47: 4108.4 | H47: 2778 | I47: 6025.3 | J47: 5897.4 | K47: 16891.9
A48: Tax | B48: 1286.4 | C48: 1075.6 | D48: 788 | E48: 332.7 | F48: 1846.5 | G48: 1232 | H48: 709.8 | I48: 1307.8 | J48: 1744 | K48: 757.3
A49: Net profit | B49: 2145.2 | C49: 1588.2 | D49: 3005.6 | E49: 1612.5 | F49: 1340.7 | G49: 2442.2 | H49: 2071.6 | I49: 4159.9 | J49: 3593.2 | K49: 14781.2
A50: Operating Profit | B50: 17593.8 | C50: 18084.8 | D50: 18697.1 | E50: 19598.5 | F50: 19513.7 | G50: 19814.8 | H50: 19364.8 | I50: 19707.6 | J50: 21846.2 | K50: 24596.6
A55: BALANCE SHEET
A56: Report Date | B56: 42094 | C56: 42460 | D56: 42825 | E56: 43190 | F56: 43555 | G56: 43921 | H56: 44286 | I56: 44651 | J56: 45016 | K56: 45382
A57: Equity Share Capital | B57: 1998.7 | C57: 1998.7 | D57: 1998.7 | E57: 1998.7 | F57: 1998.7 | G57: 2727.8 | H57: 2746 | I57: 2795 | J57: 2836.6 | K57: 2876.6
A58: Reserves | B58: 37778.3 | C58: 64770.6 | D58: 65457.6 | E58: 67535.7 | F58: 69423.5 | G58: 74417 | H58: 56206.7 | I58: 63759.3 | J58: 74726.3 | K58: 79142.2
...

Sheet Airtel-Tata 
H3: FCFE=FCF−Interest×(1−Tax Rate)+Net Borrowing
B4: Parameters | C4: Bidder (BHARTIARTL) | D4: Target (TATACOMM) | E4: No synergy | F4: With Synergy | H4: Formula Used for FCFE
B5: Free Cashflow to Equity | C5: =Airtel!K95-(Airtel!K89*(1-Airtel!D122))+Airtel!K22 -> 228277.27 | D5: ='Tata Comm'!K93-('Tata Comm'!K87*(1-'Tata Comm'!D120))+'Tata Comm'!K22 -> 7504.2197 | E5: =C5+D5 -> 235781.49 | F5: ='Combined Entity '!L23-'Combined Entity '!L15*(1-'Combined Entity '!E28)+'Combined Entity '!Q28 -> 256115.96 | H5: (Sales -(depreciation+Marketing exp + SG&A)-Interest)*(1-tax%) +depreciation - capex - NWC change
B6: Growth rate for first 5 years | C6: =Airtel!R78 -> 0.25 | D6: ='Tata Comm'!R77 -> 0.1 | E6: =C6*($D$28/($D$28+$F$28))+D6*($F$28/($D$28+$F$28)) -> 0.24278231 | F6: 0.25
B7: Beta | C7: =Airtel!P122 -> 0.34 | D7: ='Tata Comm'!P120 -> 0.57
B8: Req. rate of return(WACC) | C8: =C16 -> 0.087445455 | D8: =D16 -> 0.063655503 | E8: =C8*($D$28/($D$28+$F$28))+D8*($F$28/($D$28+$F$28)) -> 0.086300732 | F8: =E8 -> 0.086300732 | H8: Current Market Price
B9: Riskfree Rate | C9: =Airtel!P131 -> 0.0675 | D9: =C9 -> 0.0675 | E9: =D9 -> 0.0675 | F9: =E9 -> 0.0675 | H9: Airtel | I9: =1575 -> 1575
H10: Tata Communications | I10: =1319 -> 1319
B11: Per share FCFE | C11: =C5/578 -> 394.94338 | D11: =D5/28.4 -> 264.23309 | M11: Growth rate
M12: =D32 -> % Premium over the Target's Computed Enterprise Value
B14: Perpetual Growth Rate | C14: 0.03 | D14: 0.03 | F14: 0.03
B16: WACC | C16: =Airtel!P127 -> 0.087445455 | D16: ='Tata Comm'!P127 -> 0.063655503 | E16: =AVERAGE(C16:D16) -> 0.075550479 | F16: =F8 -> 0.086300732
B22: YEAR | C22: FCF (A) | D22: Term Val (A) | E22: FCF (B) | F22: Term. Val (B) | G22: FCF (A+B) | H22: TV (A+B) | I22: FCF (A+B:S) | J22: TV (A+B:S)
B23: 1 | C23: =C5*(1+C6) -> 285346.59 | E23: =D5*(1+D6) -> 8254.6416 | G23: =C23+E23 -> 293601.23 | I23: =F5 -> 256115.96
B24: 2 | C24: =C23*(1+C6) -> 356683.24 | E24: =E23*(1+D6) -> 9080.1058 | G24: =C24+E24 -> 365763.35 | I24: =I23*(1+$F$6) -> 320144.95
B25: 3 | C25: =C24*(1+C7) -> 477955.54 | E25: =E24*(1+D7) -> 14255.766 | G25: =C25+E25 -> 492211.31 | I25: =I24*(1+$F$6) -> 400181.19
B26: 4 | C26: =C25*(1+C8) -> 519750.58 | E26: =E25*(1+D8) -> 15163.224 | G26: =C26+E26 -> 534913.8 | I26: =I25*(1+$F$6) -> 500226.48
B27: 5 | C27: =C26*(1+C9) -> 554833.74 | D27: =C27*(1+C14)/(C16-C14) -> 9948197.9 | E27: =E26*(1+D9) -> 16186.742 | F27: =E27*(1+D14)/(D16-D14) -> 495382.4 | G27: =C27+E27 -> 571020.49 | H27: =D27+F27 -> 10443580 | I27: =I26*(1+$F$6) -> 625283.11 | J27: =I27*(1+F14)/(F16-F14) -> 11439311
B28: PRESENT VALUE | D28: =C23/(1+C16)+C24/(1+C16)^2+C25/(1+C16)^3+C26/(1+C16)^4+(C27+D27)/(1+C16)^5 -> 8214185.1 | F28: =E23/(1+D16)+E24/(1+D16)^2+E25/(1+D16)^3+E26/(1+D16)^4+(E27+F27)/(1+D16)^5 -> 415229.65 | H28: =G23/(1+E16)+G24/(1+E16)^2+G25/(1+E16)^3+G26/(1+E16)^4+(G27+H27)/(1+E16)^5 -> 9037189.2 | J28: =I23/(1+F16)+I24/(1+F16)^2+I25/(1+F16)^3+I26/(1+F16)^4+(I27+J27)/(1+F16)^5 -> 9154054.4
D30: Synergy gain (TakeOver Premium) | G30: =J28-H28 -> 116865.27
D31: Most that bidder firm can bid for target | G31: =F28+G30 -> 532094.92
D32: % Premium over the Target's Computed Enterprise Value | G32: =G30/F28 -> 0.28144731
A33: Number of Shares | D33: Reservation Price/Share | G33: =G31/284.975845 -> 1867.158
A34: Airtel | B34: 5787470634
A35: Tata Communications | B35: 284975845 | F35: Premium Over the CMP | G35: =G33/I10-1 -> 0.41558604

Sheet Combined Entity 
C3: 42094 | D3: 42460 | E3: 42825 | F3: 43190 | G3: 43555 | H3: 43921 | I3: 44286 | J3: 44651 | K3: 45016 | L3: 45382 | M3: 45747 | N3: 46112 | O3: 46477 | P3: 46843 | Q3: 47208 | R3: 47573
B4: Sales | C4: ='Tata Comm'!B77+Airtel!B77 -> 117547.88 | D4: ='Tata Comm'!C77+Airtel!C77 -> 119621.1 | E4: ='Tata Comm'!D77+Airtel!D77 -> 116094.95 | F4: ='Tata Comm'!E77+Airtel!E77 -> 101051.13 | G4: ='Tata Comm'!F77+Airtel!F77 -> 101841.75 | H4: ='Tata Comm'!G77+Airtel!G77 -> 66511.56 | I4: ='Tata Comm'!H77+Airtel!H77 -> 113582.94 | J4: ='Tata Comm'!I77+Airtel!I77 -> 138265.78 | ... L4: ='Tata Comm'!K77+Airtel!K77 -> 167570.53 | M4: =L4*(1+M5) -> 206111.75 | N4: =M4*(1+N5) -> 253517.45 | O4: =N4*(1+O5) -> 311826.47 | P4: =O4*(1+P5) -> 386664.82 | Q4: =P4*(1+Q5) -> 479464.38 | R4: =Q4*(1+R5) -> 594535.83
B5: Sales Growth % | D5: =D4/C4-1 -> 0.017637239 | E5: =E4/D4-1 -> -0.029477659 | F5: =F4/E4-1 -> -0.12958204 | G5: =G4/F4-1 -> 0.00782396 | H5: =H4/G4-1 -> -0.34691264 | I5: =I4/H4-1 -> 0.70771728 | J5: =J4/I4-1 -> 0.21731116 | K5: =K4/J4-1 -> 0.14591955 | L5: =L4/K4-1 -> 0.057617937 | M5: 0.23 | N5: 0.23 | O5: 0.23 | P5: 0.24 | Q5: 0.24 | R5: 0.24
B6: Cost of Goods Sold | C6: ='Tata Comm'!B78+Airtel!B79 -> 52673.38 | D6: ='Tata Comm'!C78+Airtel!C79 -> 52187.94 | E6: ='Tata Comm'!D78+Airtel!D79 -> 51774.15 | F6: ='Tata Comm'!E78+Airtel!E79 -> 46811.07 | G6: ='Tata Comm'!F78+Airtel!F79 -> 48666.26 | H6: ='Tata Comm'!G78+Airtel!G79 -> 48023.36 | I6: ='Tata Comm'!H78+Airtel!H79 -> 52660.8 | J6: ='Tata Comm'!I78+Airtel!I79 -> 54354.51 | ... R6: ='Tata Comm'!Q78+Airtel!Q79 -> 98689.076
B7: COGS % of Sales | C7: =C6/C4 -> 0.44810149 | D7: =D6/D4 -> 0.43627704 | E7: =E6/E4 -> 0.44596384 | F7: =F6/F4 -> 0.46324143 | G7: =G6/G4 -> 0.47786158 | H7: =H6/H4 -> 0.72203028 | I7: =I6/I4 -> 0.46363301 | J7: =J6/J4 -> 0.39311614 | ... R7: =R6/R4 -> 0.16599349
B8: Gross profit | C8: =C4-C6 -> 64874.5 | D8: =D4-D6 -> 67433.16 | E8: =E4-E6 -> 64320.8 | F8: =F4-F6 -> 54240.06 | G8: =G4-G6 -> 53175.49 | H8: =H4-H6 -> 18488.2 | I8: =I4-I6 -> 60922.14 | J8: =J4-J6 -> 83911.27 | ... R8: =R4-R6 -> 495846.75
B9: Operating Expenses | C9: =Airtel!B82+'Tata Comm'!B81 -> 27734.21 | D9: =Airtel!C82+'Tata Comm'!C81 -> 26074.3 | E9: =Airtel!D82+'Tata Comm'!D81 -> 23578.18 | F9: =Airtel!E82+'Tata Comm'!E81 -> 20108.1 | G9: =Airtel!F82+'Tata Comm'!F81 -> 20130.24 | H9: =Airtel!G82+'Tata Comm'!G81 -> 16685.18 | I9: =Airtel!H82+'Tata Comm'!H81 -> 15515.62 | J9: =Airtel!I82+'Tata Comm'!I81 -> 17156.5 | ... R9: =Airtel!Q82+'Tata Comm'!Q81 -> 106380.89
B10: Opex % of Sales | C10: =C9/C4 -> 0.23593969 | D10: =D9/D4 -> 0.21797409 | E10: =E9/E4 -> 0.20309393 | F10: =F9/F4 -> 0.19898936 | G10: =G9/G4 -> 0.19766196 | H10: =H9/H4 -> 0.25086135 | I10: =I9/I4 -> 0.13660168 | J10: =J9/J4 -> 0.12408349 | ... R10: =R9/R4 -> 0.17893099
